Workbook

Sheet Print
A1: Bundle: | B1: =Users!A2 | C1: Bundle: | D1: =Users!A1 | E1: Bundle: | F1: =Users!A3
A2: User: | B2: =Users!B2 | C2: User: | D2: =Users!B1 | E2: User: | F2: =Users!B3
A3: Password: | B3: =Users!C2 | C3: Password: | D3: =Users!C1 | E3: Password: | F3: =Users!C3
A4: Bundle: | B4: =Users!A4 | C4: Bundle: | D4: =Users!A5 | E4: Bundle: | F4: =Users!A6
A5: User: | B5: =Users!B4 | C5: User: | D5: =Users!B5 | E5: User: | F5: =Users!B6
A6: Password: | B6: =Users!C4 | C6: Password: | D6: =Users!C5 | E6: Password: | F6: =Users!C6
A7: Bundle: | B7: =Users!A7 | C7: Bundle: | D7: =Users!A8 | E7: Bundle: | F7: =Users!A9
A8: User: | B8: =Users!B7 | C8: User: | D8: =Users!B8 | E8: User: | F8: =Users!B9
A9: Password: | B9: =Users!C7 | C9: Password: | D9: =Users!C8 | E9: Password: | F9: =Users!C9
A10: Bundle: | B10: =Users!A10 | C10: Bundle: | D10: =Users!A11 | E10: Bundle: | F10: =Users!A12
A11: User: | B11: =Users!B10 | C11: User: | D11: =Users!B11 | E11: User: | F11: =Users!B12
A12: Password: | B12: =Users!C10 | C12: Password: | D12: =Users!C11 | E12: Password: | F12: =Users!C12
A13: Bundle: | B13: =Users!A13 | C13: Bundle: | D13: =Users!A14 | E13: Bundle: | F13: =Users!A15
A14: User: | B14: =Users!B13 | C14: User: | D14: =Users!B14 | E14: User: | F14: =Users!B15
A15: Password: | B15: =Users!C13 | C15: Password: | D15: =Users!C14 | E15: Password: | F15: =Users!C15
A16: Bundle: | B16: =Users!A16 | C16: Bundle: | D16: =Users!A17 | E16: Bundle: | F16: =Users!A18
A17: User: | B17: =Users!B16 | C17: User: | D17: =Users!B17 | E17: User: | F17: =Users!B18
A18: Password: | B18: =Users!C16 | C18: Password: | D18: =Users!C17 | E18: Password: | F18: =Users!C18
A19: Bundle: | B19: =Users!A19 | C19: Bundle: | D19: =Users!A20 | E19: Bundle: | F19: =Users!A21
A20: User: | B20: =Users!B19 | C20: User: | D20: =Users!B20 | E20: User: | F20: =Users!B21
A21: Password: | B21: =Users!C19 | C21: Password: | D21: =Users!C20 | E21: Password: | F21: =Users!C21
A22: Bundle: | B22: =Users!A22 | C22: Bundle: | D22: =Users!A23 | E22: Bundle: | F22: =Users!A24
A23: User: | B23: =Users!B22 | C23: User: | D23: =Users!B23 | E23: User: | F23: =Users!B24
A24: Password: | B24: =Users!C22 | C24: Password: | D24: =Users!C23 | E24: Password: | F24: =Users!C24
A25: Bundle: | B25: =Users!A25 | C25: Bundle: | D25: =Users!A26 | E25: Bundle: | F25: =Users!A27
A26: User: | B26: =Users!B25 | C26: User: | D26: =Users!B26 | E26: User: | F26: =Users!B27
A27: Password: | B27: =Users!C25 | C27: Password: | D27: =Users!C26 | E27: Password: | F27: =Users!C27
A28: Bundle: | B28: =Users!A28 | C28: Bundle: | D28: =Users!A29 | E28: Bundle: | F28: =Users!A30
A29: User: | B29: =Users!B28 | C29: User: | D29: =Users!B29 | E29: User: | F29: =Users!B30
A30: Password: | B30: =Users!C28 | C30: Password: | D30: =Users!C29 | E30: Password: | F30: =Users!C30
A31: Bundle: | B31: =Users!A31 | C31: Bundle: | D31: =Users!A32 | E31: Bundle: | F31: =Users!A33
A32: User: | B32: =Users!B31 | C32: User: | D32: =Users!B32 | E32: User: | F32: =Users!B33
A33: Password: | B33: =Users!C31 | C33: Password: | D33: =Users!C32 | E33: Password: | F33: =Users!C33
A34: Bundle: | B34: =Users!A34 | C34: Bundle: | D34: =Users!A35 | E34: Bundle: | F34: =Users!A36
A35: User: | B35: =Users!B34 | C35: User: | D35: =Users!B35 | E35: User: | F35: =Users!B36
A36: Password: | B36: =Users!C34 | C36: Password: | D36: =Users!C35 | E36: Password: | F36: =Users!C36
A37: Bundle: | B37: =Users!A37 | C37: Bundle: | D37: =Users!A38 | E37: Bundle: | F37: =Users!A39
A38: User: | B38: =Users!B37 | C38: User: | D38: =Users!B38 | E38: User: | F38: =Users!B39
A39: Password: | B39: =Users!C37 | C39: Password: | D39: =Users!C38 | E39: Password: | F39: =Users!C39
A40: Bundle: | B40: =Users!A40 | C40: Bundle: | D40: =Users!A41 | E40: Bundle: | F40: =Users!A42
...

Sheet Users
A1: =IFERROR(_xlfn.TEXTBEFORE(_xlfn.TEXTAFTER('From Mikrotik User-Manager'!A1,"comment=")," "),"") | B1: =IFERROR(_xlfn.TEXTBEFORE(_xlfn.TEXTAFTER('From Mikrotik User-Manager'!A1,"name=")," "),"") | C1: =IFERROR(_xlfn.TEXTBEFORE(_xlfn.TEXTAFTER('From Mikrotik User-Manager'!A1,"password=")," "),"")
A2: =IFERROR(_xlfn.TEXTBEFORE(_xlfn.TEXTAFTER('From Mikrotik User-Manager'!A2,"comment=")," "),"") | B2: =IFERROR(_xlfn.TEXTBEFORE(_xlfn.TEXTAFTER('From Mikrotik User-Manager'!A2,"name=")," "),"") | C2: =IFERROR(_xlfn.TEXTBEFORE(_xlfn.TEXTAFTER('From Mikrotik User-Manager'!A2,"password=")," "),"")
A3: =IFERROR(_xlfn.TEXTBEFORE(_xlfn.TEXTAFTER('From Mikrotik User-Manager'!A3,"comment=")," "),"") | B3: =IFERROR(_xlfn.TEXTBEFORE(_xlfn.TEXTAFTER('From Mikrotik User-Manager'!A3,"name=")," "),"") | C3: =IFERROR(_xlfn.TEXTBEFORE(_xlfn.TEXTAFTER('From Mikrotik User-Manager'!A3,"password=")," "),"")
A4: =IFERROR(_xlfn.TEXTBEFORE(_xlfn.TEXTAFTER('From Mikrotik User-Manager'!A4,"comment=")," "),"") | B4: =IFERROR(_xlfn.TEXTBEFORE(_xlfn.TEXTAFTER('From Mikrotik User-Manager'!A4,"name=")," "),"") | C4: =IFERROR(_xlfn.TEXTBEFORE(_xlfn.TEXTAFTER('From Mikrotik User-Manager'!A4,"password=")," "),"")
A5: =IFERROR(_xlfn.TEXTBEFORE(_xlfn.TEXTAFTER('From Mikrotik User-Manager'!A5,"comment=")," "),"") | B5: =IFERROR(_xlfn.TEXTBEFORE(_xlfn.TEXTAFTER('From Mikrotik User-Manager'!A5,"name=")," "),"") | C5: =IFERROR(_xlfn.TEXTBEFORE(_xlfn.TEXTAFTER('From Mikrotik User-Manager'!A5,"password=")," "),"")
A6: =IFERROR(_xlfn.TEXTBEFORE(_xlfn.TEXTAFTER('From Mikrotik User-Manager'!A6,"comment=")," "),"") | B6: =IFERROR(_xlfn.TEXTBEFORE(_xlfn.TEXTAFTER('From Mikrotik User-Manager'!A6,"name=")," "),"") | C6: =IFERROR(_xlfn.TEXTBEFORE(_xlfn.TEXTAFTER('From Mikrotik User-Manager'!A6,"password=")," "),"")
A7: =IFERROR(_xlfn.TEXTBEFORE(_xlfn.TEXTAFTER('From Mikrotik User-Manager'!A7,"comment=")," "),"") | B7: =IFERROR(_xlfn.TEXTBEFORE(_xlfn.TEXTAFTER('From Mikrotik User-Manager'!A7,"name=")," "),"") | C7: =IFERROR(_xlfn.TEXTBEFORE(_xlfn.TEXTAFTER('From Mikrotik User-Manager'!A7,"password=")," "),"")
A8: =IFERROR(_xlfn.TEXTBEFORE(_xlfn.TEXTAFTER('From Mikrotik User-Manager'!A8,"comment=")," "),"") | B8: =IFERROR(_xlfn.TEXTBEFORE(_xlfn.TEXTAFTER('From Mikrotik User-Manager'!A8,"name=")," "),"") | C8: =IFERROR(_xlfn.TEXTBEFORE(_xlfn.TEXTAFTER('From Mikrotik User-Manager'!A8,"password=")," "),"")
A9: =IFERROR(_xlfn.TEXTBEFORE(_xlfn.TEXTAFTER('From Mikrotik User-Manager'!A9,"comment=")," "),"") | B9: =IFERROR(_xlfn.TEXTBEFORE(_xlfn.TEXTAFTER('From Mikrotik User-Manager'!A9,"name=")," "),"") | C9: =IFERROR(_xlfn.TEXTBEFORE(_xlfn.TEXTAFTER('From Mikrotik User-Manager'!A9,"password=")," "),"")
A10: =IFERROR(_xlfn.TEXTBEFORE(_xlfn.TEXTAFTER('From Mikrotik User-Manager'!A10,"comment=")," "),"") | B10: =IFERROR(_xlfn.TEXTBEFORE(_xlfn.TEXTAFTER('From Mikrotik User-Manager'!A10,"name=")," "),"") | C10: =IFERROR(_xlfn.TEXTBEFORE(_xlfn.TEXTAFTER('From Mikrotik User-Manager'!A10,"password=")," "),"")
A11: =IFERROR(_xlfn.TEXTBEFORE(_xlfn.TEXTAFTER('From Mikrotik User-Manager'!A11,"comment=")," "),"") | B11: =IFERROR(_xlfn.TEXTBEFORE(_xlfn.TEXTAFTER('From Mikrotik User-Manager'!A11,"name=")," "),"") | C11: =IFERROR(_xlfn.TEXTBEFORE(_xlfn.TEXTAFTER('From Mikrotik User-Manager'!A11,"password=")," "),"")
A12: =IFERROR(_xlfn.TEXTBEFORE(_xlfn.TEXTAFTER('From Mikrotik User-Manager'!A12,"comment=")," "),"") | B12: =IFERROR(_xlfn.TEXTBEFORE(_xlfn.TEXTAFTER('From Mikrotik User-Manager'!A12,"name=")," "),"") | C12: =IFERROR(_xlfn.TEXTBEFORE(_xlfn.TEXTAFTER('From Mikrotik User-Manager'!A12,"password=")," "),"")
... A4000: =IFERROR(_xlfn.TEXTBEFORE(_xlfn.TEXTAFTER('From Mikrotik User-Manager'!A4000,"comment=")," "),"") | B4000: =IFERROR(_xlfn.TEXTBEFORE(_xlfn.TEXTAFTER('From Mikrotik User-Manager'!A4000,"name=")," "),"") | C4000: =IFERROR(_xlfn.TEXTBEFORE(_xlfn.TEXTAFTER('From Mikrotik User-Manager'!A4000,"password=")," "),"")

Sheet From Mikrotik User-Manager

Sheet Command
A1: /user-manager/user export show-sensitive terse file=user.txt.rsc where comment=2026-03-31
